
The following have been reloaded with a version change:
  1) gcc/4.8.5 => gcc/11.4.0

Traceback (most recent call last):
  File "/cluster/scratch/trgabl/hpclab_personal/project_4_raw/powermethod/benchmark_weak.py", line 62, in <module>
    main()
  File "/cluster/scratch/trgabl/hpclab_personal/project_4_raw/powermethod/benchmark_weak.py", line 41, in main
    run(threads[i], int(n_x * np.sqrt(threads[i])), n_t)
  File "/cluster/scratch/trgabl/hpclab_personal/project_4_raw/powermethod/benchmark_weak.py", line 11, in run
    output = subprocess.check_output(
             ^^^^^^^^^^^^^^^^^^^^^^^^
  File "/cluster/apps/nss/gcc-11.4.0/python/3.11.6/x86_64/lib64/python3.11/subprocess.py", line 466, in check_output
    return run(*popenargs, stdout=PIPE, timeout=timeout, check=True,
           ^^^^^^^^^^^^^^^^^^^^^^^^^^^^^^^^^^^^^^^^^^^^^^^^^^^^^^^^^
  File "/cluster/apps/nss/gcc-11.4.0/python/3.11.6/x86_64/lib64/python3.11/subprocess.py", line 550, in run
    stdout, stderr = process.communicate(input, timeout=timeout)
                     ^^^^^^^^^^^^^^^^^^^^^^^^^^^^^^^^^^^^^^^^^^^
  File "/cluster/apps/nss/gcc-11.4.0/python/3.11.6/x86_64/lib64/python3.11/subprocess.py", line 1196, in communicate
    stdout = self.stdout.read()
             ^^^^^^^^^^^^^^^^^^
OSError: [Errno 14] Bad address
