
Inactive Modules:
  1) code-server/4.16.1     2) git/2.31.1

The following have been reloaded with a version change:
  1) gcc/8.2.0 => gcc/11.4.0                3) python/3.8.5 => python/3.11.6
  2) openblas/0.2.20 => openblas/0.3.20

--------------------------------------------------------------------------
ORTE has lost communication with a remote daemon.

  HNP daemon   : [[60326,0],0] on node eu-a2p-341
  Remote daemon: [[60326,0],5] on node eu-a2p-350

This is usually due to either a failure of the TCP network
connection to the node, or possibly an internal failure of
the daemon itself. We cannot recover from this failure, and
therefore will terminate the job.
--------------------------------------------------------------------------
Traceback (most recent call last):
  File "/cluster/scratch/trgabl/hpclab_personal/project_4_raw/powermethod/benchmark_weak.py", line 62, in <module>
    main()
  File "/cluster/scratch/trgabl/hpclab_personal/project_4_raw/powermethod/benchmark_weak.py", line 43, in main
    times_par.append(run(threads[i], int(n_x * np.sqrt(threads[i])), n_t))
                     ^^^^^^^^^^^^^^^^^^^^^^^^^^^^^^^^^^^^^^^^^^^^^^^^^^^^
  File "/cluster/scratch/trgabl/hpclab_personal/project_4_raw/powermethod/benchmark_weak.py", line 11, in run
    output = subprocess.check_output(
             ^^^^^^^^^^^^^^^^^^^^^^^^
  File "/cluster/apps/nss/gcc-11.4.0/python/3.11.6/x86_64/lib64/python3.11/subprocess.py", line 466, in check_output
    return run(*popenargs, stdout=PIPE, timeout=timeout, check=True,
           ^^^^^^^^^^^^^^^^^^^^^^^^^^^^^^^^^^^^^^^^^^^^^^^^^^^^^^^^^
  File "/cluster/apps/nss/gcc-11.4.0/python/3.11.6/x86_64/lib64/python3.11/subprocess.py", line 571, in run
    raise CalledProcessError(retcode, process.args,
subprocess.CalledProcessError: Command '['mpirun', '-np', '16', './powermethod_rows', '3', '8000', '3000', '-1e-6']' returned non-zero exit status 205.
